<?xml version="1.0"?>
<sdf version="1.9">
  <model name="robot">

    <pose>0 0 0.05 0 0 0</pose>

    <!-- ================= BASE ================= -->
    <link name="base_link">
      <pose>0 0 0.05 0 0 0</pose>

      <inertial>
        <mass>1.5</mass>
        <inertia>
          <ixx>0.02</ixx>
          <iyy>0.02</iyy>
          <izz>0.04</izz>
        </inertia>
      </inertial>

      <collision name="base_collision">
        <geometry>
          <box>
            <size>0.18 0.14 0.10</size>
          </box>
        </geometry>
      </collision>

      <visual name="base_visual">
        <geometry>
          <box>
            <size>0.18 0.14 0.10</size>
          </box>
        </geometry>
        <material>
          <ambient>0.8 0.8 0.8 1</ambient>
          <diffuse>0.8 0.8 0.8 1</diffuse>
        </material>
      </visual>

      <!-- IMU -->
      <sensor name="imu" type="imu">
        <always_on>true</always_on>
        <update_rate>200</update_rate>
        <topic>/model/robot/imu</topic>
      </sensor>

      <!-- GPS -->
      <sensor name="gps" type="gps">
        <always_on>true</always_on>
        <update_rate>5</update_rate>
        <topic>/model/robot/gps</topic>
      </sensor>

      <!-- 2D LIDAR -->
      <sensor name="lidar" type="gpu_lidar">
        <pose>0.09 0 0.12 0 0 0</pose>
        <update_rate>10</update_rate>
        <topic>/scan</topic>

        <lidar>
          <scan>
            <horizontal>
              <samples>720</samples>
              <min_angle>-3.14159</min_angle>
              <max_angle>3.14159</max_angle>
            </horizontal>
          </scan>
          <range>
            <min>0.05</min>
            <max>6.0</max>
          </range>
        </lidar>
      </sensor>
    </link>

    <!-- ================= LEFT WHEEL ================= -->
    <link name="left_wheel">
      <!-- IMPORTANT: roll = 1.5708 to align cylinder axis with Y -->
      <pose>0 0.07 0.03 1.5708 0 0</pose>

      <inertial>
        <mass>0.2</mass>
        <inertia>
          <ixx>0.001</ixx>
          <iyy>0.001</iyy>
          <izz>0.001</izz>
        </inertia>
      </inertial>

      <collision name="collision">
        <geometry>
          <cylinder>
            <radius>0.03</radius>
            <length>0.02</length>
          </cylinder>
        </geometry>
      </collision>

      <visual name="visual">
        <geometry>
          <cylinder>
            <radius>0.03</radius>
            <length>0.02</length>
          </cylinder>
        </geometry>
        <material>
          <ambient>0.1 0.1 0.1 1</ambient>
        </material>
      </visual>
    </link>

    <!-- ================= RIGHT WHEEL ================= -->
    <link name="right_wheel">
      <pose>0 -0.07 0.03 1.5708 0 0</pose>

      <inertial>
        <mass>0.2</mass>
        <inertia>
          <ixx>0.001</ixx>
          <iyy>0.001</iyy>
          <izz>0.001</izz>
        </inertia>
      </inertial>

      <collision name="collision">
        <geometry>
          <cylinder>
            <radius>0.03</radius>
            <length>0.02</length>
          </cylinder>
        </geometry>
      </collision>

      <visual name="visual">
        <geometry>
          <cylinder>
            <radius>0.03</radius>
            <length>0.02</length>
          </cylinder>
        </geometry>
        <material>
          <ambient>0.1 0.1 0.1 1</ambient>
        </material>
      </visual>
    </link>

    <!-- ================= JOINTS ================= -->
    <joint name="left_wheel_joint" type="revolute">
      <parent>base_link</parent>
      <child>left_wheel</child>
      <axis>
        <xyz>0 1 0</xyz>
      </axis>
    </joint>

    <joint name="right_wheel_joint" type="revolute">
      <parent>base_link</parent>
      <child>right_wheel</child>
      <axis>
        <xyz>0 1 0</xyz>
      </axis>
    </joint>

    <!-- ================= DIFF DRIVE ================= -->
    <plugin
      filename="gz-sim-diff-drive-system"
      name="gz::sim::systems::DiffDrive">

      <left_joint>left_wheel_joint</left_joint>
      <right_joint>right_wheel_joint</right_joint>

      <wheel_separation>0.14</wheel_separation>
      <wheel_radius>0.03</wheel_radius>

      <cmd_vel_topic>/model/robot/cmd_vel</cmd_vel_topic>
      <odom_topic>/model/robot/odom</odom_topic>
      <odom_publish_frequency>50</odom_publish_frequency>

      <publish_tf>false</publish_tf>
    </plugin>

  </model>
</sdf>
