<?xml version="1.0"?>
<sdf version="1.9">
  <model name="robot">
    <static>false</static>

    <!-- Dimensions (meters):
         Length  = 0.135
         Width   = 0.090   (2/3 of 0.135)
         Height  = 0.135
         Wheel diameter = 0.040  (radius 0.020)
    -->

    <!-- ================= CHASSIS ================= -->
    <link name="chassis">
      <pose>0 0 0.0675 0 0 0</pose>

      <inertial>
        <mass>1.0</mass>
        <inertia>
          <ixx>0.002</ixx>
          <ixy>0</ixy>
          <ixz>0</ixz>
          <iyy>0.002</iyy>
          <iyz>0</iyz>
          <izz>0.002</izz>
        </inertia>
      </inertial>

      <collision name="chassis_collision">
        <geometry>
          <box>
            <size>0.135 0.090 0.135</size>
          </box>
        </geometry>
      </collision>

      <visual name="chassis_visual">
        <geometry>
          <box>
            <size>0.135 0.090 0.135</size>
          </box>
        </geometry>
        <material>
          <ambient>0.2 0.2 0.8 1</ambient>
          <diffuse>0.2 0.2 0.8 1</diffuse>
        </material>
      </visual>

      <!-- IMU -->
      <sensor name="imu" type="imu">
        <always_on>true</always_on>
        <update_rate>100</update_rate>
        <topic>/model/robot/imu</topic>
      </sensor>

      <!-- Camera -->
      <sensor name="camera" type="camera">
        <pose>0.060 0 0.060 0 0 0</pose>
        <always_on>true</always_on>
        <update_rate>30</update_rate>
        <topic>/model/robot/camera/image</topic>
        <camera>
          <horizontal_fov>1.047</horizontal_fov>
          <image>
            <width>640</width>
            <height>480</height>
            <format>R8G8B8</format>
          </image>
          <clip>
            <near>0.02</near>
            <far>10</far>
          </clip>
        </camera>
      </sensor>

      <!-- 2D lidar -->
      <sensor name="lidar" type="gpu_lidar">
        <pose>0 0 0.120 0 0 0</pose>
        <always_on>true</always_on>
        <update_rate>15</update_rate>
        <topic>/model/robot/scan</topic>
        <lidar>
          <scan>
            <horizontal>
              <samples>720</samples>
              <resolution>1</resolution>
              <min_angle>-3.14159</min_angle>
              <max_angle>3.14159</max_angle>
            </horizontal>
          </scan>
          <range>
            <min>0.02</min>
            <max>6.0</max>
            <resolution>0.01</resolution>
          </range>
        </lidar>
      </sensor>
    </link>

    <!-- ================= LEFT WHEEL ================= -->
    <link name="left_wheel">
      <pose>0 0.065 0.020 0 1.57079632679 0</pose>

      <inertial>
        <mass>0.10</mass>
        <inertia>
          <ixx>0.00005</ixx>
          <ixy>0</ixy>
          <ixz>0</ixz>
          <iyy>0.00005</iyy>
          <iyz>0</iyz>
          <izz>0.00005</izz>
        </inertia>
      </inertial>

      <collision name="left_wheel_collision">
        <geometry>
          <cylinder>
            <radius>0.020</radius>
            <length>0.010</length>
          </cylinder>
        </geometry>
        <surface>
          <friction>
            <ode>
              <mu>1.2</mu>
              <mu2>1.2</mu2>
            </ode>
          </friction>
        </surface>
      </collision>

      <visual name="left_wheel_visual">
        <geometry>
          <cylinder>
            <radius>0.020</radius>
            <length>0.010</length>
          </cylinder>
        </geometry>
        <material>
          <ambient>0.05 0.05 0.05 1</ambient>
          <diffuse>0.05 0.05 0.05 1</diffuse>
        </material>
      </visual>
    </link>

    <!-- ================= RIGHT WHEEL ================= -->
    <link name="right_wheel">
      <pose>0 -0.065 0.020 0 1.57079632679 0</pose>

      <inertial>
        <mass>0.10</mass>
        <inertia>
          <ixx>0.00005</ixx>
          <ixy>0</ixy>
          <ixz>0</ixz>
          <iyy>0.00005</iyy>
          <iyz>0</iyz>
          <izz>0.00005</izz>
        </inertia>
      </inertial>

      <collision name="right_wheel_collision">
        <geometry>
          <cylinder>
            <radius>0.020</radius>
            <length>0.010</length>
          </cylinder>
        </geometry>
        <surface>
          <friction>
            <ode>
              <mu>1.2</mu>
              <mu2>1.2</mu2>
            </ode>
          </friction>
        </surface>
      </collision>

      <visual name="right_wheel_visual">
        <geometry>
          <cylinder>
            <radius>0.020</radius>
            <length>0.010</length>
          </cylinder>
        </geometry>
        <material>
          <ambient>0.05 0.05 0.05 1</ambient>
          <diffuse>0.05 0.05 0.05 1</diffuse>
        </material>
      </visual>
    </link>

    <!-- ================= JOINTS ================= -->
    <joint name="left_wheel_joint" type="revolute">
      <parent>chassis</parent>
      <child>left_wheel</child>
      <pose>0 0.065 0.020 0 0 0</pose>
      <axis>
        <xyz>0 1 0</xyz>
        <limit>
          <lower>-1e16</lower>
          <upper>1e16</upper>
        </limit>
        <dynamics>
          <damping>0.1</damping>
          <friction>0.0</friction>
        </dynamics>
      </axis>
    </joint>

    <joint name="right_wheel_joint" type="revolute">
      <parent>chassis</parent>
      <child>right_wheel</child>
      <pose>0 -0.065 0.020 0 0 0</pose>
      <axis>
        <xyz>0 1 0</xyz>
        <limit>
          <lower>-1e16</lower>
          <upper>1e16</upper>
        </limit>
        <dynamics>
          <damping>0.1</damping>
          <friction>0.0</friction>
        </dynamics>
      </axis>
    </joint>

    <!-- ================= DIFF DRIVE ================= -->
    <plugin filename="gz-sim-diff-drive-system" name="gz::sim::systems::DiffDrive">
      <left_joint>left_wheel_joint</left_joint>
      <right_joint>right_wheel_joint</right_joint>

      <wheel_separation>0.130</wheel_separation>
      <wheel_radius>0.020</wheel_radius>

      <topic>/model/robot/cmd_vel</topic>

      <!-- prevents "keeps going forever" if you publish once -->
      <command_timeout>0.15</command_timeout>

      <odom_publish_frequency>50</odom_publish_frequency>
      <odom_topic>/model/robot/odom</odom_topic>

      <left_wheel_axis>0 1 0</left_wheel_axis>
      <right_wheel_axis>0 1 0</right_wheel_axis>
    </plugin>
  </model>
</sdf>
